Workbook

Sheet Cover
A4: 乾 科 技 股 份 有 限 公 司
A5: Cyntec Co., Ltd.
A7: CIM 設備規範書
A8: CIM Equipment spec
A9: 【營錡酸洗】
A12: 編號 No | B12: 版 本 Version | C12: 內 容 Content | D12: 日期 Date | E12: 備 註 Remark
A13: 1 | B13: 1.0 | C13: CIM Equipment spec. | D13: 04/7/26
A14: 2 | B14: 1.1 | C14: Update | D14: 04/8/26
A15: 3 | B15: 1.2 | C15: Add Common Adress and Flow Chart | D15: 04/14/26

Sheet Spec.
A1: SUBJECT | C1: Equipment CIM Data Mapping
C2: Doc. No. : | D2: =Cover!C13 -> CIM Equipment spec.
A4: Equipment | C4: =Cover!A9 -> 【營錡酸洗】
A5: Data Concentrator | C5: 【Loader】
A10: Equipment Report Data
B12: （Network Parameter ） | D12: PLC Area
D13: Points | E13: Begin | F13: End
B14: Common | C14: Data | D14: 200 | E14: DM10000 | F14: DM10199
B15: Loader | C15: Data | D15: 480 | E15: DM11000 | F15: DM11479
B16: Pickling | C16: Data | D16: 150 | E16: DM12000 | F16: DM12149
B17: Unloader | C17: Data | D17: 440 | E17: DM13000 | F17: DM13439

Sheet Flow

Sheet Common Adress
A1: SUBJECT | B1: Equipment Data Mapping
B2: Doc. No. : | D2: =Cover!C13 -> CIM Equipment spec.
A3: PLC Start Adress | C3: DM10000
A5: PLC Address | B5: Name Designation | C5: Permission | D5: Format(F->0) | H5: Description | I5: Annotation
A6: [遠端指令PP_Select : RemoteCMD PP_Select]
A7: =LEFT($C$3, 2) & (MID($C$3, 3, LEN($C$3)) + J7) -> DM10000 | B7: RecipeID_Loader | C7: L->L | D7: uuuu | E7: uuuu | F7: uuuu | G7: uuuu | H7: RecipeID Change for Loader | I7: UINT(1) 1~65535 | J7: 0
A8: =LEFT($C$3, 2) & (MID($C$3, 3, LEN($C$3)) + J8) -> DM10001 | B8: RecipeID_Pickling | C8: L->D | D8: uuuu | E8: uuuu | F8: uuuu | G8: uuuu | H8: RecipeID Change for Pickling | I8: UINT(1) 1~65535 | J8: 1
A9: =LEFT($C$3, 2) & (MID($C$3, 3, LEN($C$3)) + J9) -> DM10002 | B9: RecipeID_Unloader | C9: L->UL | D9: uuuu | E9: uuuu | F9: uuuu | G9: uuuu | H9: RecipeID Change for Unloader | I9: UINT(1) 1~65535 | J9: 2
A10: =LEFT($C$3, 2) & (MID($C$3, 3, LEN($C$3)) + J10) -> DM10003 | B10: Spare | J10: 3
A11: =LEFT($C$3, 2) & (MID($C$3, 3, LEN($C$3)) + J11) -> DM10004 | B11: Spare | J11: 4
A12: =LEFT($C$3, 2) & (MID($C$3, 3, LEN($C$3)) + J12) -> DM10005 | B12: Spare | J12: 5
A13: =LEFT($C$3, 2) & (MID($C$3, 3, LEN($C$3)) + J13) -> DM10006 | B13: Spare | J13: 6
A14: =LEFT($C$3, 2) & (MID($C$3, 3, LEN($C$3)) + J14) -> DM10007 | B14: Spare | J14: 7
A15: =LEFT($C$3, 2) & (MID($C$3, 3, LEN($C$3)) + J15) -> DM10008 | B15: Spare | J15: 8
A16: =LEFT($C$3, 2) & (MID($C$3, 3, LEN($C$3)) + J16) -> DM10009 | B16: Spare | J16: 9
A17: =LEFT($C$3, 2) & (MID($C$3, 3, LEN($C$3)) + J17) -> DM10010 | B17: Current_RecipeID_Loader | C17: Common | D17: uuuu | E17: uuuu | F17: uuuu | G17: uuuu | H17: RecipeID Change for Loader | I17: UINT(1) 1~65535 | J17: 10
A18: =LEFT($C$3, 2) & (MID($C$3, 3, LEN($C$3)) + J18) -> DM10011 | B18: Current_RecipeID_Pickling | C18: Common | D18: uuuu | E18: uuuu | F18: uuuu | G18: uuuu | H18: RecipeID Change for Pickling | I18: UINT(1) 1~65535 | J18: 11
A19: =LEFT($C$3, 2) & (MID($C$3, 3, LEN($C$3)) + J19) -> DM10012 | B19: Current_RecipeID_Unloader | C19: Common | D19: uuuu | E19: uuuu | F19: uuuu | G19: uuuu | H19: RecipeID Change for Unloader | I19: UINT(1) 1~65535 | J19: 12
A20: =LEFT($C$3, 2) & (MID($C$3, 3, LEN($C$3)) + J20) -> DM10013 | B20: Spare | J20: 13
A21: =LEFT($C$3, 2) & (MID($C$3, 3, LEN($C$3)) + J21) -> DM10014 | B21: Spare | J21: 14
A22: =LEFT($C$3, 2) & (MID($C$3, 3, LEN($C$3)) + J22) -> DM10015 | B22: Spare | J22: 15
A23: =LEFT($C$3, 2) & (MID($C$3, 3, LEN($C$3)) + J23) -> DM10016 | B23: Spare | J23: 16
A24: =LEFT($C$3, 2) & (MID($C$3, 3, LEN($C$3)) + J24) -> DM10017 | B24: Spare | J24: 17
A25: =LEFT($C$3, 2) & (MID($C$3, 3, LEN($C$3)) + J25) -> DM10018 | B25: Spare | J25: 18
A26: =LEFT($C$3, 2) & (MID($C$3, 3, LEN($C$3)) + J26) -> DM10019 | B26: Spare | J26: 19
A27: [共用資料區 : Common Data Area]
A28: =LEFT($C$3, 2) & (MID($C$3, 3, LEN($C$3)) + J28) -> DM10020 | B28: WorkOrder_1 | C28: Common | D28: 2nd Char | F28: 1st Char | H28: Work Order 1 Number | I28: String (10) ASCII | J28: 20
A29: =LEFT($C$3, 2) & (MID($C$3, 3, LEN($C$3)) + J29) -> DM10021 | D29: 4th Char | F29: 3rd Char | J29: 21
A30: =LEFT($C$3, 2) & (MID($C$3, 3, LEN($C$3)) + J30) -> DM10022 | D30: 6th Char | F30: 5th Char | J30: 22
A31: =LEFT($C$3, 2) & (MID($C$3, 3, LEN($C$3)) + J31) -> DM10023 | D31: 8th Char | F31: 7th Char | J31: 23
A32: =LEFT($C$3, 2) & (MID($C$3, 3, LEN($C$3)) + J32) -> DM10024 | D32: 10th Char | F32: 9th Char | J32: 24
A33: =LEFT($C$3, 2) & (MID($C$3, 3, LEN($C$3)) + J33) -> DM10025 | D33: 12th Char | F33: 11th Char | J33: 25
A34: =LEFT($C$3, 2) & (MID($C$3, 3, LEN($C$3)) + J34) -> DM10026 | D34: 14th Char | F34: 13th Char | J34: 26
A35: =LEFT($C$3, 2) & (MID($C$3, 3, LEN($C$3)) + J35) -> DM10027 | D35: 16th Char | F35: 15th Char | J35: 27
A36: =LEFT($C$3, 2) & (MID($C$3, 3, LEN($C$3)) + J36) -> DM10028 | D36: 18th Char | F36: 17th Char | J36: 28
A37: =LEFT($C$3, 2) & (MID($C$3, 3, LEN($C$3)) + J37) -> DM10029 | D37: 20th Char | F37: 19th Char | J37: 29
A38: =LEFT($C$3, 2) & (MID($C$3, 3, LEN($C$3)) + J38) -> DM10030 | B38: WorkOrder_2 | C38: Common | D38: 2nd Char | F38: 1st Char | H38: Work Order 2 Number | I38: String (10) ASCII | J38: 30
A39: =LEFT($C$3, 2) & (MID($C$3, 3, LEN($C$3)) + J39) -> DM10031 | D39: 4th Char | F39: 3rd Char | J39: 31
A40: =LEFT($C$3, 2) & (MID($C$3, 3, LEN($C$3)) + J40) -> DM10032 | D40: 6th Char | F40: 5th Char | J40: 32
A41: =LEFT($C$3, 2) & (MID($C$3, 3, LEN($C$3)) + J41) -> DM10033 | D41: 8th Char | F41: 7th Char | J41: 33
...

Sheet Loader Adress
A1: SUBJECT | B1: Equipment Data Mapping
B2: Doc. No. : | D2: =Cover!C13 -> CIM Equipment spec.
A3: PLC Start Adress | C3: DM11000
A5: PLC Address | B5: Name Designation | C5: Permission | D5: Format(F->0) | H5: Description | I5: Annotation
A6: [觸發訊號 : Request and Ack]
A7: =LEFT($C$3, 2) & (MID($C$3, 3, LEN($C$3)) + J7) -> DM11000 | B7: Equipment Event Request | C7: EQ->EAP | D7: 0000 | E7: 0000 | F7: 000e | G7: dcba | H7: a : UserID_Verify b : TrackInReq c : AlarmReport d : StatusChangeReport e : PanelInReport | I7: (binary) | J7: 000
A8: =LEFT($C$3, 2) & (MID($C$3, 3, LEN($C$3)) + J8) -> DM11001 | B8: EAP Event Ack | C8: EAP->EQ | D8: 0 | E8: 0000 | F8: 000e | G8: dcba | H8: a : UserID_Verify b : TrackInReq c : AlarmReport d : StatusChangeReport e : PanelInReport | I8: (binary) | J8: 001
A9: =LEFT($C$3, 2) & (MID($C$3, 3, LEN($C$3)) + J9) -> DM11002 | B9: EAP CMD Request | C9: EAP->EQ | D9: p000 | E9: 0 | F9: 0 | G9: 000a | H9: a : RemoteCMD (PP_SELECT) | J9: 002
A10: =LEFT($C$3, 2) & (MID($C$3, 3, LEN($C$3)) + J10) -> DM11003 | B10: Equipment CMD Ack | C10: EQ->EAP | D10: 0 | E10: 0 | F10: 0 | G10: 000a | H10: a : RemoteCMD (PP_SELECT) | J10: 003
A11: =LEFT($C$3, 2) & (MID($C$3, 3, LEN($C$3)) + J11) -> DM11004 | B11: AliveCheck (EQ Startup) | C11: EQ->EAP | D11: 0 | E11: 0 | F11: 0 | G11: 000a | H11: a : AliveCheck (EQ Startup)，ON/OFF once every 15 seconds. | J11: 004
A12: =LEFT($C$3, 2) & (MID($C$3, 3, LEN($C$3)) + J12) -> DM11005 | B12: AliveCheck (EAP StartUp) | C12: EAP->EQ | D12: 0 | E12: 0 | F12: 0 | G12: 000a | H12: a : AliveCheck (EAP StartUp)，ON/OFF once every 15 seconds. | J12: 005
A13: [人員登入驗證 : UserID_Verify Area]
A14: =LEFT($C$3, 2) & (MID($C$3, 3, LEN($C$3)) + J14) -> DM11100 | B14: Machine | C14: EQ->EAP | D14: 2nd Char | F14: 1st Char | H14: Machine ID | I14: String (3) ASCII | J14: 100
A15: =LEFT($C$3, 2) & (MID($C$3, 3, LEN($C$3)) + J15) -> DM11101 | D15: 4th Char | F15: 3rd Char | J15: 101
A16: =LEFT($C$3, 2) & (MID($C$3, 3, LEN($C$3)) + J16) -> DM11102 | D16: 6th Char | F16: 5th Char | J16: 102
A17: =LEFT($C$3, 2) & (MID($C$3, 3, LEN($C$3)) + J17) -> DM11103 | B17: DATE | C17: EQ->EAP | D17: y(2st Char) | F17: y(1st Char) | H17: yyyyMMddHHmmss | I17: String (7) ASCII | J17: 103
A18: =LEFT($C$3, 2) & (MID($C$3, 3, LEN($C$3)) + J18) -> DM11104 | D18: y(4st Char) | F18: y(3st Char) | J18: 104
A19: =LEFT($C$3, 2) & (MID($C$3, 3, LEN($C$3)) + J19) -> DM11105 | D19: M(2st Char) | F19: M(1st Char) | J19: 105
A20: =LEFT($C$3, 2) & (MID($C$3, 3, LEN($C$3)) + J20) -> DM11106 | D20: d(2st Char) | F20: d(1st Char) | J20: 106
A21: =LEFT($C$3, 2) & (MID($C$3, 3, LEN($C$3)) + J21) -> DM11107 | D21: H(2st Char) | F21: H(1st Char) | J21: 107
A22: =LEFT($C$3, 2) & (MID($C$3, 3, LEN($C$3)) + J22) -> DM11108 | D22: m(2st Char) | F22: m(1st Char) | J22: 108
A23: =LEFT($C$3, 2) & (MID($C$3, 3, LEN($C$3)) + J23) -> DM11109 | D23: s(2st Char) | F23: s(1st Char) | J23: 109
A24: =LEFT($C$3, 2) & (MID($C$3, 3, LEN($C$3)) + J24) -> DM11110 | B24: UserID | C24: EQ->EAP | D24: 2nd Char | F24: 1st Char | H24: User ID | I24: String (3) ASCII | J24: 110
A25: =LEFT($C$3, 2) & (MID($C$3, 3, LEN($C$3)) + J25) -> DM11111 | D25: 4th Char | F25: 3rd Char | J25: 111
A26: =LEFT($C$3, 2) & (MID($C$3, 3, LEN($C$3)) + J26) -> DM11112 | D26: 6th Char | F26: 5th Char | J26: 112
A27: =LEFT($C$3, 2) & (MID($C$3, 3, LEN($C$3)) + J27) -> DM11113 | B27: Barcode | C27: EQ->EAP | D27: 2nd Char | F27: 1st Char | H27: Barcode | I27: String (24) ASCII | J27: 113
A28: =LEFT($C$3, 2) & (MID($C$3, 3, LEN($C$3)) + J28) -> DM11114 | D28: 4th Char | F28: 3rd Char | J28: 114
A29: =LEFT($C$3, 2) & (MID($C$3, 3, LEN($C$3)) + J29) -> DM11115 | D29: 6th Char | F29: 5th Char | J29: 115
A30: =LEFT($C$3, 2) & (MID($C$3, 3, LEN($C$3)) + J30) -> DM11116 | D30: 8th Char | F30: 7th Char | J30: 116
A31: =LEFT($C$3, 2) & (MID($C$3, 3, LEN($C$3)) + J31) -> DM11117 | D31: 10th Char | F31: 9th Char | J31: 117
A32: =LEFT($C$3, 2) & (MID($C$3, 3, LEN($C$3)) + J32) -> DM11118 | D32: 12th Char | F32: 11th Char | J32: 118
A33: =LEFT($C$3, 2) & (MID($C$3, 3, LEN($C$3)) + J33) -> DM11119 | D33: 14th Char | F33: 13th Char | J33: 119
A34: =LEFT($C$3, 2) & (MID($C$3, 3, LEN($C$3)) + J34) -> DM11120 | D34: 16th Char | F34: 15th Char | J34: 120
A35: =LEFT($C$3, 2) & (MID($C$3, 3, LEN($C$3)) + J35) -> DM11121 | D35: 18th Char | F35: 17th Char | J35: 121
A36: =LEFT($C$3, 2) & (MID($C$3, 3, LEN($C$3)) + J36) -> DM11122 | D36: 20th Char | F36: 19th Char | J36: 122
A37: =LEFT($C$3, 2) & (MID($C$3, 3, LEN($C$3)) + J37) -> DM11123 | D37: 22nd Char | F37: 21st Char | J37: 123
A38: =LEFT($C$3, 2) & (MID($C$3, 3, LEN($C$3)) + J38) -> DM11124 | D38: 24th Char | F38: 23rd Char | J38: 124
A39: =LEFT($C$3, 2) & (MID($C$3, 3, LEN($C$3)) + J39) -> DM11125 | D39: 26th Char | F39: 25th Char | J39: 125
... A50: =LEFT($C$3, 2) & (MID($C$3, 3, LEN($C$3)) + J50) -> DM11136 | D50: 48th Char | F50: 47th Char | J50: 136
A51: =LEFT($C$3, 2) & (MID($C$3, 3, LEN($C$3)) + J51) -> DM11137 | B51: Spare | J51: 137
...

Sheet Pickling Adress
A1: SUBJECT | B1: Equipment Data Mapping
B2: Doc. No. : | D2: =Cover!C13 -> CIM Equipment spec.
A3: PLC Start Adress | C3: DM12000
A5: PLC Address | B5: Name Designation | C5: Permission | D5: Format(F->0) | H5: Description | I5: Annotation
A6: [觸發訊號 : Request and Ack]
A7: =LEFT($C$3, 2) & (MID($C$3, 3, LEN($C$3)) + J7) -> DM12000 | B7: Equipment Event Request | C7: EQ->EAP | D7: 0000 | E7: 0000 | F7: 0000 | G7: 00ba | H7: a : AlarmReport b : StatusChangeReport | I7: (binary) | J7: 000
A8: =LEFT($C$3, 2) & (MID($C$3, 3, LEN($C$3)) + J8) -> DM12001 | B8: EAP Event Ack | C8: EAP->EQ | D8: 0 | E8: 0000 | F8: 0000 | G8: 00ba | H8: a : AlarmReport b : StatusChangeReport | I8: (binary) | J8: 001
A9: =LEFT($C$3, 2) & (MID($C$3, 3, LEN($C$3)) + J9) -> DM12002 | B9: EAP CMD Request | C9: EAP->EQ | D9: 0000 | E9: 0 | F9: 0 | G9: 0000 | J9: 002
A10: =LEFT($C$3, 2) & (MID($C$3, 3, LEN($C$3)) + J10) -> DM12003 | B10: Equipment CMD Ack | C10: EQ->EAP | D10: 0 | E10: 0 | F10: 0 | G10: 0000 | J10: 003
A11: =LEFT($C$3, 2) & (MID($C$3, 3, LEN($C$3)) + J11) -> DM12004 | B11: AliveCheck (EQ Startup) | C11: EQ->EAP | D11: 0 | E11: 0 | F11: 0 | G11: 000a | H11: a : AliveCheck (EQ Startup)，ON/OFF once every 15 seconds. | J11: 004
A12: =LEFT($C$3, 2) & (MID($C$3, 3, LEN($C$3)) + J12) -> DM12005 | B12: AliveCheck (EAP StartUp) | C12: EAP->EQ | D12: 0 | E12: 0 | F12: 0 | G12: 000a | H12: a : AliveCheck (EAP StartUp)，ON/OFF once every 15 seconds. | J12: 005
A13: [警報上報 : AlarmReport]
A14: =LEFT($C$3, 2) & (MID($C$3, 3, LEN($C$3)) + J14) -> DM12100 | B14: Machine | C14: EQ->EAP | D14: 2nd Char | F14: 1st Char | H14: Machine ID | I14: String (3) ASCII | J14: 100
A15: =LEFT($C$3, 2) & (MID($C$3, 3, LEN($C$3)) + J15) -> DM12101 | D15: 4th Char | F15: 3rd Char | J15: 101
A16: =LEFT($C$3, 2) & (MID($C$3, 3, LEN($C$3)) + J16) -> DM12102 | D16: 6th Char | F16: 5th Char | J16: 102
A17: =LEFT($C$3, 2) & (MID($C$3, 3, LEN($C$3)) + J17) -> DM12103 | B17: DATE | C17: EQ->EAP | D17: y(2st Char) | F17: y(1st Char) | H17: yyyyMMddHHmmss | I17: String (7) ASCII | J17: 103
A18: =LEFT($C$3, 2) & (MID($C$3, 3, LEN($C$3)) + J18) -> DM12104 | D18: y(4st Char) | F18: y(3st Char) | J18: 104
A19: =LEFT($C$3, 2) & (MID($C$3, 3, LEN($C$3)) + J19) -> DM12105 | D19: M(2st Char) | F19: M(1st Char) | J19: 105
A20: =LEFT($C$3, 2) & (MID($C$3, 3, LEN($C$3)) + J20) -> DM12106 | D20: d(2st Char) | F20: d(1st Char) | J20: 106
A21: =LEFT($C$3, 2) & (MID($C$3, 3, LEN($C$3)) + J21) -> DM12107 | D21: H(2st Char) | F21: H(1st Char) | J21: 107
A22: =LEFT($C$3, 2) & (MID($C$3, 3, LEN($C$3)) + J22) -> DM12108 | D22: m(2st Char) | F22: m(1st Char) | J22: 108
A23: =LEFT($C$3, 2) & (MID($C$3, 3, LEN($C$3)) + J23) -> DM12109 | D23: s(2st Char) | F23: s(1st Char) | J23: 109
A24: =LEFT($C$3, 2) & (MID($C$3, 3, LEN($C$3)) + J24) -> DM12110 | B24: AlarmStatus | C24: EQ->EAP | D24: 0 | E24: 0 | F24: 0 | G24: 00aa | H24: 1 : S / 2 : E | I24: INT(1) | J24: 110
A25: =LEFT($C$3, 2) & (MID($C$3, 3, LEN($C$3)) + J25) -> DM12111 | B25: AlarmType | C25: EQ->EAP | D25: 0 | E25: 0 | F25: 0 | G25: 00aa | H25: 1 : Alarm / 2 :Warning | I25: INT(1) | J25: 111
A26: =LEFT($C$3, 2) & (MID($C$3, 3, LEN($C$3)) + J26) -> DM12112 | B26: AlarmCode | C26: EQ->EAP | D26: 2nd Char | F26: 1st Char | H26: Alarm Code | I26: String (2) ASCII | J26: 112
A27: =LEFT($C$3, 2) & (MID($C$3, 3, LEN($C$3)) + J27) -> DM12113 | D27: 4th Char | F27: 3rd Char | J27: 113
A28: =LEFT($C$3, 2) & (MID($C$3, 3, LEN($C$3)) + J28) -> DM12114 | B28: Spare | J28: 114
A29: =LEFT($C$3, 2) & (MID($C$3, 3, LEN($C$3)) + J29) -> DM12115 | B29: Spare | J29: 115
A30: =LEFT($C$3, 2) & (MID($C$3, 3, LEN($C$3)) + J30) -> DM12116 | B30: Spare | J30: 116
A31: =LEFT($C$3, 2) & (MID($C$3, 3, LEN($C$3)) + J31) -> DM12117 | B31: Spare | J31: 117
A32: =LEFT($C$3, 2) & (MID($C$3, 3, LEN($C$3)) + J32) -> DM12118 | B32: Spare | J32: 118
A33: =LEFT($C$3, 2) & (MID($C$3, 3, LEN($C$3)) + J33) -> DM12119 | B33: Spare | J33: 119
A34: =LEFT($C$3, 2) & (MID($C$3, 3, LEN($C$3)) + J34) -> DM12120 | B34: Spare | J34: 120
A35: =LEFT($C$3, 2) & (MID($C$3, 3, LEN($C$3)) + J35) -> DM12121 | B35: RtnResult | C35: EAP->EQ | D35: 0 | E35: 0 | F35: 0 | G35: 00aa | H35: 1 : PASS / 2 :FAIL | I35: INT(1) | J35: 121
A36: =LEFT($C$3, 2) & (MID($C$3, 3, LEN($C$3)) + J36) -> DM12122 | B36: RtnCode | C36: EAP->EQ | D36: 0 | E36: 0 | F36: hhhh | G36: hhhh | H36: PASS : 0 / FAIL : 1~99 | I36: INT(2) | J36: 122
A37: =LEFT($C$3, 2) & (MID($C$3, 3, LEN($C$3)) + J37) -> DM12123 | D37: 4th Char | F37: 3rd Char | J37: 123
A38: =LEFT($C$3, 2) & (MID($C$3, 3, LEN($C$3)) + J38) -> DM12124 | D38: 6th Char | F38: 5th Char | J38: 124
A39: =LEFT($C$3, 2) & (MID($C$3, 3, LEN($C$3)) + J39) -> DM12125 | D39: 8th Char | F39: 7th Char | J39: 125
A40: =LEFT($C$3, 2) & (MID($C$3, 3, LEN($C$3)) + J40) -> DM12126 | B40: Spare | J40: 126
A41: =LEFT($C$3, 2) & (MID($C$3, 3, LEN($C$3)) + J41) -> DM12127 | B41: Spare | J41: 127
...

Sheet Unoader Adress
A1: SUBJECT | B1: Equipment Data Mapping
B2: Doc. No. : | D2: =Cover!C13 -> CIM Equipment spec.
A3: PLC Start Adress | C3: DM13000
A5: PLC Address | B5: Name Designation | C5: Permission | D5: Format(F->0) | H5: Description | I5: Annotation
A6: [觸發訊號 : Request and Ack]
A7: =LEFT($C$3, 2) & (MID($C$3, 3, LEN($C$3)) + J7) -> DM13000 | B7: Equipment Event Request | C7: EQ->EAP | D7: 0000 | E7: 0000 | F7: 000e | G7: dcba | H7: a : UserID_Verify b : TrackOutReq c : AlarmReport d : StatusChangeReport e : PanelOutReport | I7: (binary) | J7: 000
A8: =LEFT($C$3, 2) & (MID($C$3, 3, LEN($C$3)) + J8) -> DM13001 | B8: EAP Event Ack | C8: EAP->EQ | D8: 0 | E8: 0000 | F8: 000e | G8: dcba | H8: a : UserID_Verify b : TrackOutReq c : AlarmReport d : StatusChangeReport e : PanelOutReport | I8: (binary) | J8: 001
A9: =LEFT($C$3, 2) & (MID($C$3, 3, LEN($C$3)) + J9) -> DM13002 | B9: EAP CMD Request | C9: EAP->EQ | D9: 0000 | E9: 0 | F9: 0 | G9: 0000 | J9: 002
A10: =LEFT($C$3, 2) & (MID($C$3, 3, LEN($C$3)) + J10) -> DM13003 | B10: Equipment CMD Ack | C10: EQ->EAP | D10: 0 | E10: 0 | F10: 0 | G10: 0000 | J10: 003
A11: =LEFT($C$3, 2) & (MID($C$3, 3, LEN($C$3)) + J11) -> DM13004 | B11: AliveCheck (EQ Startup) | C11: EQ->EAP | D11: 0 | E11: 0 | F11: 0 | G11: 000a | H11: a : AliveCheck (EQ Startup)，ON/OFF once every 15 seconds. | J11: 004
A12: =LEFT($C$3, 2) & (MID($C$3, 3, LEN($C$3)) + J12) -> DM13005 | B12: AliveCheck (EAP StartUp) | C12: EAP->EQ | D12: 0 | E12: 0 | F12: 0 | G12: 000a | H12: a : AliveCheck (EAP StartUp)，ON/OFF once every 15 seconds. | J12: 005
A13: [人員登入驗證 : UserID_Verify Area]
A14: =LEFT($C$3, 2) & (MID($C$3, 3, LEN($C$3)) + J14) -> DM13100 | B14: Machine | C14: EQ->EAP | D14: 2nd Char | F14: 1st Char | H14: Machine ID | I14: String (3) ASCII | J14: 100
A15: =LEFT($C$3, 2) & (MID($C$3, 3, LEN($C$3)) + J15) -> DM13101 | D15: 4th Char | F15: 3rd Char | J15: 101
A16: =LEFT($C$3, 2) & (MID($C$3, 3, LEN($C$3)) + J16) -> DM13102 | D16: 6th Char | F16: 5th Char | J16: 102
A17: =LEFT($C$3, 2) & (MID($C$3, 3, LEN($C$3)) + J17) -> DM13103 | B17: DATE | C17: EQ->EAP | D17: y(2st Char) | F17: y(1st Char) | H17: yyyyMMddHHmmss | I17: String (7) ASCII | J17: 103
A18: =LEFT($C$3, 2) & (MID($C$3, 3, LEN($C$3)) + J18) -> DM13104 | D18: y(4st Char) | F18: y(3st Char) | J18: 104
A19: =LEFT($C$3, 2) & (MID($C$3, 3, LEN($C$3)) + J19) -> DM13105 | D19: M(2st Char) | F19: M(1st Char) | J19: 105
A20: =LEFT($C$3, 2) & (MID($C$3, 3, LEN($C$3)) + J20) -> DM13106 | D20: d(2st Char) | F20: d(1st Char) | J20: 106
A21: =LEFT($C$3, 2) & (MID($C$3, 3, LEN($C$3)) + J21) -> DM13107 | D21: H(2st Char) | F21: H(1st Char) | J21: 107
A22: =LEFT($C$3, 2) & (MID($C$3, 3, LEN($C$3)) + J22) -> DM13108 | D22: m(2st Char) | F22: m(1st Char) | J22: 108
A23: =LEFT($C$3, 2) & (MID($C$3, 3, LEN($C$3)) + J23) -> DM13109 | D23: s(2st Char) | F23: s(1st Char) | J23: 109
A24: =LEFT($C$3, 2) & (MID($C$3, 3, LEN($C$3)) + J24) -> DM13110 | B24: UserID | C24: EQ->EAP | D24: 2nd Char | F24: 1st Char | H24: User ID | I24: String (3) ASCII | J24: 110
A25: =LEFT($C$3, 2) & (MID($C$3, 3, LEN($C$3)) + J25) -> DM13111 | D25: 4th Char | F25: 3rd Char | J25: 111
A26: =LEFT($C$3, 2) & (MID($C$3, 3, LEN($C$3)) + J26) -> DM13112 | D26: 6th Char | F26: 5th Char | J26: 112
A27: =LEFT($C$3, 2) & (MID($C$3, 3, LEN($C$3)) + J27) -> DM13113 | B27: Barcode | C27: EQ->EAP | D27: 2nd Char | F27: 1st Char | H27: Barcode | I27: String (24) ASCII | J27: 113
A28: =LEFT($C$3, 2) & (MID($C$3, 3, LEN($C$3)) + J28) -> DM13114 | D28: 4th Char | F28: 3rd Char | J28: 114
A29: =LEFT($C$3, 2) & (MID($C$3, 3, LEN($C$3)) + J29) -> DM13115 | D29: 6th Char | F29: 5th Char | J29: 115
A30: =LEFT($C$3, 2) & (MID($C$3, 3, LEN($C$3)) + J30) -> DM13116 | D30: 8th Char | F30: 7th Char | J30: 116
A31: =LEFT($C$3, 2) & (MID($C$3, 3, LEN($C$3)) + J31) -> DM13117 | D31: 10th Char | F31: 9th Char | J31: 117
A32: =LEFT($C$3, 2) & (MID($C$3, 3, LEN($C$3)) + J32) -> DM13118 | D32: 12th Char | F32: 11th Char | J32: 118
A33: =LEFT($C$3, 2) & (MID($C$3, 3, LEN($C$3)) + J33) -> DM13119 | D33: 14th Char | F33: 13th Char | J33: 119
A34: =LEFT($C$3, 2) & (MID($C$3, 3, LEN($C$3)) + J34) -> DM13120 | D34: 16th Char | F34: 15th Char | J34: 120
A35: =LEFT($C$3, 2) & (MID($C$3, 3, LEN($C$3)) + J35) -> DM13121 | D35: 18th Char | F35: 17th Char | J35: 121
A36: =LEFT($C$3, 2) & (MID($C$3, 3, LEN($C$3)) + J36) -> DM13122 | D36: 20th Char | F36: 19th Char | J36: 122
A37: =LEFT($C$3, 2) & (MID($C$3, 3, LEN($C$3)) + J37) -> DM13123 | D37: 22nd Char | F37: 21st Char | J37: 123
A38: =LEFT($C$3, 2) & (MID($C$3, 3, LEN($C$3)) + J38) -> DM13124 | D38: 24th Char | F38: 23rd Char | J38: 124
A39: =LEFT($C$3, 2) & (MID($C$3, 3, LEN($C$3)) + J39) -> DM13125 | D39: 26th Char | F39: 25th Char | J39: 125
... A50: =LEFT($C$3, 2) & (MID($C$3, 3, LEN($C$3)) + J50) -> DM13136 | D50: 48th Char | F50: 47th Char | J50: 136
A51: =LEFT($C$3, 2) & (MID($C$3, 3, LEN($C$3)) + J51) -> DM13137 | B51: Spare | J51: 137
...
